{
    "parts": [
        {
            "x": 2,
            "y": 3,
            "z": 0,
            "elements": [
                "gregtech:turbine_casing@4"
            ]
        },
        {
            "x": -3,
            "y": 0,
            "z": 4,
            "elements": [
                "gregtech:turbine_casing@4"
            ]
        },
        {
            "x": -4,
            "y": 2,
            "z": 4,
            "elements": [
                "gregtech:turbine_casing@4"
            ]
        },
        {
            "x": 5,
            "y": 0,
            "z": 2,
            "elements": [
                "gregtech:turbine_casing@4"
            ]
        },
        {
            "x": 5,
            "y": 0,
            "z": 3,
            "elements": [
                "gregtech:turbine_casing@4"
            ]
        },
        {
            "x": -4,
            "y": 2,
            "z": 0,
            "elements": [
                "gregtech:turbine_casing@4"
            ]
        },
        {
            "x": 5,
            "y": 0,
            "z": 1,
            "elements": [
                "gregtech:turbine_casing@4"
            ]
        },
        {
            "x": 3,
            "y": 1,
            "z": 0,
            "elements": [
                "gregtech:turbine_casing@4"
            ]
        },
        {
            "x": -5,
            "y": 4,
            "z": 1,
            "elements": [
                "gregtech:turbine_casing@4"
            ]
        },
        {
            "x": -5,
            "y": 4,
            "z": 2,
            "elements": [
                "gregtech:turbine_casing@4"
            ]
        },
        {
            "x": 2,
            "y": 3,
            "z": 4,
            "elements": [
                "gregtech:turbine_casing@4"
            ]
        },
        {
            "x": 4,
            "y": 2,
            "z": 4,
            "elements": [
                "gregtech:turbine_casing@4"
            ]
        },
        {
            "x": -5,
            "y": 4,
            "z": 3,
            "elements": [
                "gregtech:turbine_casing@4"
            ]
        },
        {
            "x": -1,
            "y": -1,
            "z": 1,
            "elements": [
                "gregtech:metal_casing@4", "modularmachinery:blockinputfluid", "modularmachinery:blockoutputfluid"item", "modularmachinery:blockinputfluid", "modularmachinery:blockoutputfluid"energy", "modularmachinery:blockinputfluid", "modularmachinery:blockoutputfluid"
            ]
        },
        {
            "x": -5,
            "y": 1,
            "z": 3,
            "elements": [
                "gregtech:turbine_casing@4"
            ]
        },
        {
            "x": -1,
            "y": -1,
            "z": 2,
            "elements": [
                "gregtech:metal_casing@4", "modularmachinery:blockinputfluid", "modularmachinery:blockoutputfluid"item", "modularmachinery:blockinputfluid", "modularmachinery:blockoutputfluid"energy", "modularmachinery:blockinputfluid", "modularmachinery:blockoutputfluid"
            ]
        },
        {
            "x": -2,
            "y": 1,
            "z": 4,
            "elements": [
                "gregtech:turbine_casing@4"
            ]
        },
        {
            "x": 3,
            "y": 4,
            "z": 0,
            "elements": [
                "gregtech:turbine_casing@4"
            ]
        },
        {
            "x": -1,
            "y": -1,
            "z": 3,
            "elements": [
                "gregtech:metal_casing@4", "modularmachinery:blockinputfluid", "modularmachinery:blockoutputfluid"item", "modularmachinery:blockinputfluid", "modularmachinery:blockoutputfluid"energy", "modularmachinery:blockinputfluid", "modularmachinery:blockoutputfluid"
            ]
        },
        {
            "x": -1,
            "y": -1,
            "z": 4,
            "elements": [
                "gregtech:metal_casing@4", "modularmachinery:blockinputfluid", "modularmachinery:blockoutputfluid"item", "modularmachinery:blockinputfluid", "modularmachinery:blockoutputfluid"energy", "modularmachinery:blockinputfluid", "modularmachinery:blockoutputfluid"
            ]
        },
        {
            "x": 4,
            "y": 2,
            "z": 0,
            "elements": [
                "gregtech:turbine_casing@4"
            ]
        },
        {
            "x": -4,
            "y": -1,
            "z": 2,
            "elements": [
                "gregtech:metal_casing@4", "modularmachinery:blockinputfluid", "modularmachinery:blockoutputfluid"item", "modularmachinery:blockinputfluid", "modularmachinery:blockoutputfluid"energy", "modularmachinery:blockinputfluid", "modularmachinery:blockoutputfluid"
            ]
        },
        {
            "x": -4,
            "y": -1,
            "z": 3,
            "elements": [
                "gregtech:metal_casing@4", "modularmachinery:blockinputfluid", "modularmachinery:blockoutputfluid"item", "modularmachinery:blockinputfluid", "modularmachinery:blockoutputfluid"energy", "modularmachinery:blockinputfluid", "modularmachinery:blockoutputfluid"
            ]
        },
        {
            "x": -4,
            "y": -1,
            "z": 0,
            "elements": [
                "gregtech:metal_casing@4", "modularmachinery:blockinputfluid", "modularmachinery:blockoutputfluid"item", "modularmachinery:blockinputfluid", "modularmachinery:blockoutputfluid"energy", "modularmachinery:blockinputfluid", "modularmachinery:blockoutputfluid"
            ]
        },
        {
            "x": 3,
            "y": 4,
            "z": 4,
            "elements": [
                "gregtech:turbine_casing@4"
            ]
        },
        {
            "x": -2,
            "y": 1,
            "z": 0,
            "elements": [
                "gregtech:turbine_casing@4"
            ]
        },
        {
            "x": -4,
            "y": -1,
            "z": 1,
            "elements": [
                "gregtech:metal_casing@4", "modularmachinery:blockinputfluid", "modularmachinery:blockoutputfluid"item", "modularmachinery:blockinputfluid", "modularmachinery:blockoutputfluid"energy", "modularmachinery:blockinputfluid", "modularmachinery:blockoutputfluid"
            ]
        },
        {
            "x": -3,
            "y": 0,
            "z": 0,
            "elements": [
                "gregtech:turbine_casing@4"
            ]
        },
        {
            "x": -5,
            "y": 1,
            "z": 1,
            "elements": [
                "gregtech:turbine_casing@4"
            ]
        },
        {
            "x": -5,
            "y": 1,
            "z": 2,
            "elements": [
                "gregtech:turbine_casing@4"
            ]
        },
        {
            "x": -1,
            "y": -1,
            "z": 0,
            "elements": [
                "gregtech:metal_casing@4", "modularmachinery:blockinputfluid", "modularmachinery:blockoutputfluid"item", "modularmachinery:blockinputfluid", "modularmachinery:blockoutputfluid"energy", "modularmachinery:blockinputfluid", "modularmachinery:blockoutputfluid"
            ]
        },
        {
            "x": -4,
            "y": 5,
            "z": 1,
            "elements": [
                "gregtech:turbine_casing@4"
            ]
        },
        {
            "x": 4,
            "y": 5,
            "z": 3,
            "elements": [
                "gregtech:turbine_casing@4"
            ]
        },
        {
            "x": 5,
            "y": 3,
            "z": 2,
            "elements": [
                "gregtech:turbine_casing@4"
            ]
        },
        {
            "x": 5,
            "y": 3,
            "z": 1,
            "elements": [
                "gregtech:turbine_casing@4"
            ]
        },
        {
            "x": 4,
            "y": 5,
            "z": 2,
            "elements": [
                "gregtech:turbine_casing@4"
            ]
        },
        {
            "x": 4,
            "y": 5,
            "z": 1,
            "elements": [
                "gregtech:turbine_casing@4"
            ]
        },
        {
            "x": 5,
            "y": 3,
            "z": 3,
            "elements": [
                "gregtech:turbine_casing@4"
            ]
        },
        {
            "x": -4,
            "y": 5,
            "z": 2,
            "elements": [
                "gregtech:turbine_casing@4"
            ]
        },
        {
            "x": 0,
            "y": 0,
            "z": 2,
            "nbt": {"id":"ic2:fluid_pipe","ForgeCaps":{"nuclearcraft:capability_default_radiation_resistance":{"radiationResistance":"0.0d","shieldingRadResistance":"0.0d"}},"facing":"3b","active":"0b","components":{"covers":{"covers":[]}},"connectivity":"12b","covers":"0b","type":"1b","size":"3b","Empty":""},
            "elements": [
                "ic2:te@12"
            ]
        },
        {
            "x": -4,
            "y": 5,
            "z": 3,
            "elements": [
                "gregtech:turbine_casing@4"
            ]
        },
        {
            "x": 1,
            "y": 2,
            "z": 3,
            "elements": [
                "gregtech:turbine_casing@4"
            ]
        },
        {
            "x": -1,
            "y": 3,
            "z": 3,
            "elements": [
                "gregtech:turbine_casing@4"
            ]
        },
        {
            "x": 1,
            "y": 2,
            "z": 2,
            "elements": [
                "gregtech:turbine_casing@4"
            ]
        },
        {
            "x": -1,
            "y": 3,
            "z": 2,
            "elements": [
                "gregtech:turbine_casing@4"
            ]
        },
        {
            "x": 1,
            "y": 2,
            "z": 1,
            "elements": [
                "gregtech:turbine_casing@4"
            ]
        },
        {
            "x": -1,
            "y": 3,
            "z": 1,
            "elements": [
                "gregtech:turbine_casing@4"
            ]
        },
        {
            "x": 1,
            "y": -1,
            "z": 2,
            "elements": [
                "gregtech:metal_casing@4", "modularmachinery:blockinputfluid", "modularmachinery:blockoutputfluid"item", "modularmachinery:blockinputfluid", "modularmachinery:blockoutputfluid"energy", "modularmachinery:blockinputfluid", "modularmachinery:blockoutputfluid"
            ]
        },
        {
            "x": 5,
            "y": 4,
            "z": 3,
            "elements": [
                "gregtech:turbine_casing@4"
            ]
        },
        {
            "x": 1,
            "y": -1,
            "z": 1,
            "elements": [
                "gregtech:metal_casing@4", "modularmachinery:blockinputfluid", "modularmachinery:blockoutputfluid"item", "modularmachinery:blockinputfluid", "modularmachinery:blockoutputfluid"energy", "modularmachinery:blockinputfluid", "modularmachinery:blockoutputfluid"
            ]
        },
        {
            "x": 5,
            "y": 4,
            "z": 2,
            "elements": [
                "gregtech:turbine_casing@4"
            ]
        },
        {
            "x": -2,
            "y": 4,
            "z": 0,
            "elements": [
                "gregtech:turbine_casing@4"
            ]
        },
        {
            "x": 1,
            "y": -1,
            "z": 0,
            "elements": [
                "gregtech:metal_casing@4", "modularmachinery:blockinputfluid", "modularmachinery:blockoutputfluid"item", "modularmachinery:blockinputfluid", "modularmachinery:blockoutputfluid"energy", "modularmachinery:blockinputfluid", "modularmachinery:blockoutputfluid"
            ]
        },
        {
            "x": 1,
            "y": -1,
            "z": 4,
            "elements": [
                "gregtech:metal_casing@4", "modularmachinery:blockinputfluid", "modularmachinery:blockoutputfluid"item", "modularmachinery:blockinputfluid", "modularmachinery:blockoutputfluid"energy", "modularmachinery:blockinputfluid", "modularmachinery:blockoutputfluid"
            ]
        },
        {
            "x": -2,
            "y": 4,
            "z": 4,
            "elements": [
                "gregtech:turbine_casing@4"
            ]
        },
        {
            "x": 5,
            "y": 4,
            "z": 1,
            "elements": [
                "gregtech:turbine_casing@4"
            ]
        },
        {
            "x": 3,
            "y": 1,
            "z": 4,
            "elements": [
                "gregtech:turbine_casing@4"
            ]
        },
        {
            "x": 1,
            "y": -1,
            "z": 3,
            "elements": [
                "gregtech:metal_casing@4", "modularmachinery:blockinputfluid", "modularmachinery:blockoutputfluid"item", "modularmachinery:blockinputfluid", "modularmachinery:blockoutputfluid"energy", "modularmachinery:blockinputfluid", "modularmachinery:blockoutputfluid"
            ]
        },
        {
            "x": -5,
            "y": 0,
            "z": 1,
            "elements": [
                "gregtech:turbine_casing@4"
            ]
        },
        {
            "x": 3,
            "y": 5,
            "z": 3,
            "elements": [
                "gregtech:turbine_casing@4"
            ]
        },
        {
            "x": -5,
            "y": 0,
            "z": 3,
            "elements": [
                "gregtech:turbine_casing@4"
            ]
        },
        {
            "x": -5,
            "y": 0,
            "z": 2,
            "elements": [
                "gregtech:turbine_casing@4"
            ]
        },
        {
            "x": 3,
            "y": 5,
            "z": 2,
            "elements": [
                "gregtech:turbine_casing@4"
            ]
        },
        {
            "x": 3,
            "y": 5,
            "z": 1,
            "elements": [
                "gregtech:turbine_casing@4"
            ]
        },
        {
            "x": 4,
            "y": 3,
            "z": 4,
            "elements": [
                "gregtech:turbine_casing@4"
            ]
        },
        {
            "x": 1,
            "y": 1,
            "z": 3,
            "elements": [
                "gregtech:turbine_casing@4"
            ]
        },
        {
            "x": 1,
            "y": 1,
            "z": 2,
            "elements": [
                "gregtech:turbine_casing@4"
            ]
        },
        {
            "x": 4,
            "y": 3,
            "z": 0,
            "elements": [
                "gregtech:turbine_casing@4"
            ]
        },
        {
            "x": 1,
            "y": 1,
            "z": 1,
            "elements": [
                "gregtech:turbine_casing@4"
            ]
        },
        {
            "x": 5,
            "y": -1,
            "z": 3,
            "elements": [
                "gregtech:metal_casing@4", "modularmachinery:blockinputfluid", "modularmachinery:blockoutputfluid"item", "modularmachinery:blockinputfluid", "modularmachinery:blockoutputfluid"energy", "modularmachinery:blockinputfluid", "modularmachinery:blockoutputfluid"
            ]
        },
        {
            "x": 5,
            "y": -1,
            "z": 4,
            "elements": [
                "gregtech:metal_casing@4", "modularmachinery:blockinputfluid", "modularmachinery:blockoutputfluid"item", "modularmachinery:blockinputfluid", "modularmachinery:blockoutputfluid"energy", "modularmachinery:blockinputfluid", "modularmachinery:blockoutputfluid"
            ]
        },
        {
            "x": 3,
            "y": 2,
            "z": 0,
            "elements": [
                "gregtech:turbine_casing@4"
            ]
        },
        {
            "x": 3,
            "y": 2,
            "z": 4,
            "elements": [
                "gregtech:turbine_casing@4"
            ]
        },
        {
            "x": 4,
            "y": 0,
            "z": 0,
            "elements": [
                "gregtech:turbine_casing@4"
            ]
        },
        {
            "x": -2,
            "y": 5,
            "z": 1,
            "elements": [
                "gregtech:turbine_casing@4"
            ]
        },
        {
            "x": -2,
            "y": 5,
            "z": 3,
            "elements": [
                "gregtech:turbine_casing@4"
            ]
        },
        {
            "x": -2,
            "y": 5,
            "z": 2,
            "elements": [
                "gregtech:turbine_casing@4"
            ]
        },
        {
            "x": -5,
            "y": 3,
            "z": 1,
            "elements": [
                "gregtech:turbine_casing@4"
            ]
        },
        {
            "x": -5,
            "y": 3,
            "z": 2,
            "elements": [
                "gregtech:turbine_casing@4"
            ]
        },
        {
            "x": -3,
            "y": 3,
            "z": 4,
            "elements": [
                "gregtech:turbine_casing@4"
            ]
        },
        {
            "x": -4,
            "y": -1,
            "z": 4,
            "elements": [
                "gregtech:metal_casing@4", "modularmachinery:blockinputfluid", "modularmachinery:blockoutputfluid"item", "modularmachinery:blockinputfluid", "modularmachinery:blockoutputfluid"energy", "modularmachinery:blockinputfluid", "modularmachinery:blockoutputfluid"
            ]
        },
        {
            "x": -5,
            "y": 3,
            "z": 3,
            "elements": [
                "gregtech:turbine_casing@4"
            ]
        },
        {
            "x": -2,
            "y": -1,
            "z": 4,
            "elements": [
                "gregtech:metal_casing@4", "modularmachinery:blockinputfluid", "modularmachinery:blockoutputfluid"item", "modularmachinery:blockinputfluid", "modularmachinery:blockoutputfluid"energy", "modularmachinery:blockinputfluid", "modularmachinery:blockoutputfluid"
            ]
        },
        {
            "x": 5,
            "y": -1,
            "z": 1,
            "elements": [
                "gregtech:metal_casing@4", "modularmachinery:blockinputfluid", "modularmachinery:blockoutputfluid"item", "modularmachinery:blockinputfluid", "modularmachinery:blockoutputfluid"energy", "modularmachinery:blockinputfluid", "modularmachinery:blockoutputfluid"
            ]
        },
        {
            "x": -3,
            "y": 3,
            "z": 0,
            "elements": [
                "gregtech:turbine_casing@4"
            ]
        },
        {
            "x": 5,
            "y": -1,
            "z": 2,
            "elements": [
                "gregtech:metal_casing@4", "modularmachinery:blockinputfluid", "modularmachinery:blockoutputfluid"item", "modularmachinery:blockinputfluid", "modularmachinery:blockoutputfluid"energy", "modularmachinery:blockinputfluid", "modularmachinery:blockoutputfluid"
            ]
        },
        {
            "x": -2,
            "y": -1,
            "z": 2,
            "elements": [
                "gregtech:metal_casing@4", "modularmachinery:blockinputfluid", "modularmachinery:blockoutputfluid"item", "modularmachinery:blockinputfluid", "modularmachinery:blockoutputfluid"energy", "modularmachinery:blockinputfluid", "modularmachinery:blockoutputfluid"
            ]
        },
        {
            "x": 5,
            "y": -1,
            "z": 0,
            "elements": [
                "gregtech:metal_casing@4", "modularmachinery:blockinputfluid", "modularmachinery:blockoutputfluid"item", "modularmachinery:blockinputfluid", "modularmachinery:blockoutputfluid"energy", "modularmachinery:blockinputfluid", "modularmachinery:blockoutputfluid"
            ]
        },
        {
            "x": -2,
            "y": -1,
            "z": 3,
            "elements": [
                "gregtech:metal_casing@4", "modularmachinery:blockinputfluid", "modularmachinery:blockoutputfluid"item", "modularmachinery:blockinputfluid", "modularmachinery:blockoutputfluid"energy", "modularmachinery:blockinputfluid", "modularmachinery:blockoutputfluid"
            ]
        },
        {
            "x": -2,
            "y": -1,
            "z": 0,
            "elements": [
                "gregtech:metal_casing@4", "modularmachinery:blockinputfluid", "modularmachinery:blockoutputfluid"item", "modularmachinery:blockinputfluid", "modularmachinery:blockoutputfluid"energy", "modularmachinery:blockinputfluid", "modularmachinery:blockoutputfluid"
            ]
        },
        {
            "x": -2,
            "y": -1,
            "z": 1,
            "elements": [
                "gregtech:metal_casing@4", "modularmachinery:blockinputfluid", "modularmachinery:blockoutputfluid"item", "modularmachinery:blockinputfluid", "modularmachinery:blockoutputfluid"energy", "modularmachinery:blockinputfluid", "modularmachinery:blockoutputfluid"
            ]
        },
        {
            "x": 1,
            "y": 4,
            "z": 1,
            "elements": [
                "gregtech:turbine_casing@4"
            ]
        },
        {
            "x": -2,
            "y": 2,
            "z": 0,
            "elements": [
                "gregtech:turbine_casing@4"
            ]
        },
        {
            "x": 2,
            "y": 0,
            "z": 0,
            "elements": [
                "gregtech:turbine_casing@4"
            ]
        },
        {
            "x": -2,
            "y": 2,
            "z": 4,
            "elements": [
                "gregtech:turbine_casing@4"
            ]
        },
        {
            "x": 5,
            "y": 2,
            "z": 1,
            "elements": [
                "gregtech:turbine_casing@4"
            ]
        },
        {
            "x": 1,
            "y": 4,
            "z": 2,
            "elements": [
                "gregtech:turbine_casing@4"
            ]
        },
        {
            "x": 2,
            "y": 0,
            "z": 4,
            "elements": [
                "gregtech:turbine_casing@4"
            ]
        },
        {
            "x": 5,
            "y": 2,
            "z": 3,
            "elements": [
                "gregtech:turbine_casing@4"
            ]
        },
        {
            "x": 5,
            "y": 2,
            "z": 2,
            "elements": [
                "gregtech:turbine_casing@4"
            ]
        },
        {
            "x": 1,
            "y": 4,
            "z": 3,
            "elements": [
                "gregtech:turbine_casing@4"
            ]
        },
        {
            "x": 1,
            "y": 0,
            "z": 3,
            "elements": [
                "gregtech:turbine_casing@4"
            ]
        },
        {
            "x": 1,
            "y": 0,
            "z": 2,
            "nbt": {"id":"ic2:fluid_pipe","ForgeCaps":{"nuclearcraft:capability_default_radiation_resistance":{"radiationResistance":"0.0d","shieldingRadResistance":"0.0d"}},"facing":"3b","active":"0b","components":{"covers":{"covers":[]}},"connectivity":"4b","covers":"0b","type":"1b","size":"3b","Empty":""},
            "elements": [
                "ic2:te@12"
            ]
        },
        {
            "x": 1,
            "y": 0,
            "z": 1,
            "elements": [
                "gregtech:turbine_casing@4"
            ]
        },
        {
            "x": -3,
            "y": 5,
            "z": 3,
            "elements": [
                "gregtech:turbine_casing@4"
            ]
        },
        {
            "x": -3,
            "y": 5,
            "z": 2,
            "elements": [
                "gregtech:turbine_casing@4"
            ]
        },
        {
            "x": -3,
            "y": 5,
            "z": 1,
            "elements": [
                "gregtech:turbine_casing@4"
            ]
        },
        {
            "x": 3,
            "y": -1,
            "z": 3,
            "elements": [
                "gregtech:metal_casing@4", "modularmachinery:blockinputfluid", "modularmachinery:blockoutputfluid"item", "modularmachinery:blockinputfluid", "modularmachinery:blockoutputfluid"energy", "modularmachinery:blockinputfluid", "modularmachinery:blockoutputfluid"
            ]
        },
        {
            "x": 3,
            "y": -1,
            "z": 4,
            "elements": [
                "gregtech:metal_casing@4", "modularmachinery:blockinputfluid", "modularmachinery:blockoutputfluid"item", "modularmachinery:blockinputfluid", "modularmachinery:blockoutputfluid"energy", "modularmachinery:blockinputfluid", "modularmachinery:blockoutputfluid"
            ]
        },
        {
            "x": 3,
            "y": -1,
            "z": 1,
            "elements": [
                "gregtech:metal_casing@4", "modularmachinery:blockinputfluid", "modularmachinery:blockoutputfluid"item", "modularmachinery:blockinputfluid", "modularmachinery:blockoutputfluid"energy", "modularmachinery:blockinputfluid", "modularmachinery:blockoutputfluid"
            ]
        },
        {
            "x": -5,
            "y": -1,
            "z": 0,
            "elements": [
                "gregtech:metal_casing@4", "modularmachinery:blockinputfluid", "modularmachinery:blockoutputfluid"item", "modularmachinery:blockinputfluid", "modularmachinery:blockoutputfluid"energy", "modularmachinery:blockinputfluid", "modularmachinery:blockoutputfluid"
            ]
        },
        {
            "x": 3,
            "y": -1,
            "z": 2,
            "elements": [
                "gregtech:metal_casing@4", "modularmachinery:blockinputfluid", "modularmachinery:blockoutputfluid"item", "modularmachinery:blockinputfluid", "modularmachinery:blockoutputfluid"energy", "modularmachinery:blockinputfluid", "modularmachinery:blockoutputfluid"
            ]
        },
        {
            "x": -1,
            "y": 1,
            "z": 3,
            "elements": [
                "gregtech:turbine_casing@4"
            ]
        },
        {
            "x": -1,
            "y": 1,
            "z": 2,
            "elements": [
                "gregtech:turbine_casing@4"
            ]
        },
        {
            "x": -5,
            "y": -1,
            "z": 2,
            "elements": [
                "gregtech:metal_casing@4", "modularmachinery:blockinputfluid", "modularmachinery:blockoutputfluid"item", "modularmachinery:blockinputfluid", "modularmachinery:blockoutputfluid"energy", "modularmachinery:blockinputfluid", "modularmachinery:blockoutputfluid"
            ]
        },
        {
            "x": 2,
            "y": 1,
            "z": 4,
            "elements": [
                "gregtech:turbine_casing@4"
            ]
        },
        {
            "x": -1,
            "y": 4,
            "z": 3,
            "elements": [
                "gregtech:turbine_casing@4"
            ]
        },
        {
            "x": -5,
            "y": -1,
            "z": 1,
            "elements": [
                "gregtech:metal_casing@4", "modularmachinery:blockinputfluid", "modularmachinery:blockoutputfluid"item", "modularmachinery:blockinputfluid", "modularmachinery:blockoutputfluid"energy", "modularmachinery:blockinputfluid", "modularmachinery:blockoutputfluid"
            ]
        },
        {
            "x": -1,
            "y": 4,
            "z": 2,
            "elements": [
                "gregtech:turbine_casing@4"
            ]
        },
        {
            "x": -1,
            "y": 1,
            "z": 1,
            "elements": [
                "gregtech:turbine_casing@4"
            ]
        },
        {
            "x": 3,
            "y": -1,
            "z": 0,
            "elements": [
                "gregtech:metal_casing@4", "modularmachinery:blockinputfluid", "modularmachinery:blockoutputfluid"item", "modularmachinery:blockinputfluid", "modularmachinery:blockoutputfluid"energy", "modularmachinery:blockinputfluid", "modularmachinery:blockoutputfluid"
            ]
        },
        {
            "x": -5,
            "y": -1,
            "z": 4,
            "elements": [
                "gregtech:metal_casing@4", "modularmachinery:blockinputfluid", "modularmachinery:blockoutputfluid"item", "modularmachinery:blockinputfluid", "modularmachinery:blockoutputfluid"energy", "modularmachinery:blockinputfluid", "modularmachinery:blockoutputfluid"
            ]
        },
        {
            "x": -1,
            "y": 4,
            "z": 1,
            "elements": [
                "gregtech:turbine_casing@4"
            ]
        },
        {
            "x": -5,
            "y": -1,
            "z": 3,
            "elements": [
                "gregtech:metal_casing@4", "modularmachinery:blockinputfluid", "modularmachinery:blockoutputfluid"item", "modularmachinery:blockinputfluid", "modularmachinery:blockoutputfluid"energy", "modularmachinery:blockinputfluid", "modularmachinery:blockoutputfluid"
            ]
        },
        {
            "x": 2,
            "y": 1,
            "z": 0,
            "elements": [
                "gregtech:turbine_casing@4"
            ]
        },
        {
            "x": 1,
            "y": 3,
            "z": 3,
            "elements": [
                "gregtech:turbine_casing@4"
            ]
        },
        {
            "x": -4,
            "y": 4,
            "z": 4,
            "elements": [
                "gregtech:turbine_casing@4"
            ]
        },
        {
            "x": -2,
            "y": 3,
            "z": 4,
            "elements": [
                "gregtech:turbine_casing@4"
            ]
        },
        {
            "x": -4,
            "y": 4,
            "z": 0,
            "elements": [
                "gregtech:turbine_casing@4"
            ]
        },
        {
            "x": -2,
            "y": 3,
            "z": 0,
            "elements": [
                "gregtech:turbine_casing@4"
            ]
        },
        {
            "x": -2,
            "y": 0,
            "z": 4,
            "elements": [
                "gregtech:turbine_casing@4"
            ]
        },
        {
            "x": 1,
            "y": 3,
            "z": 1,
            "elements": [
                "gregtech:turbine_casing@4"
            ]
        },
        {
            "x": -5,
            "y": 2,
            "z": 2,
            "elements": [
                "gregtech:turbine_casing@4"
            ]
        },
        {
            "x": -5,
            "y": 2,
            "z": 3,
            "elements": [
                "gregtech:turbine_casing@4"
            ]
        },
        {
            "x": 1,
            "y": 3,
            "z": 2,
            "elements": [
                "gregtech:turbine_casing@4"
            ]
        },
        {
            "x": 2,
            "y": 5,
            "z": 1,
            "elements": [
                "gregtech:turbine_casing@4"
            ]
        },
        {
            "x": 4,
            "y": 0,
            "z": 4,
            "elements": [
                "gregtech:turbine_casing@4"
            ]
        },
        {
            "x": 2,
            "y": 5,
            "z": 2,
            "elements": [
                "gregtech:turbine_casing@4"
            ]
        },
        {
            "x": 4,
            "y": 1,
            "z": 0,
            "elements": [
                "gregtech:turbine_casing@4"
            ]
        },
        {
            "x": 2,
            "y": 5,
            "z": 3,
            "elements": [
                "gregtech:turbine_casing@4"
            ]
        },
        {
            "x": 4,
            "y": 1,
            "z": 4,
            "elements": [
                "gregtech:turbine_casing@4"
            ]
        },
        {
            "x": -4,
            "y": 1,
            "z": 0,
            "elements": [
                "gregtech:turbine_casing@4"
            ]
        },
        {
            "x": -2,
            "y": 0,
            "z": 0,
            "elements": [
                "gregtech:turbine_casing@4"
            ]
        },
        {
            "x": -4,
            "y": 1,
            "z": 4,
            "elements": [
                "gregtech:turbine_casing@4"
            ]
        },
        {
            "x": 4,
            "y": 4,
            "z": 0,
            "elements": [
                "gregtech:turbine_casing@4"
            ]
        },
        {
            "x": 2,
            "y": 2,
            "z": 0,
            "elements": [
                "gregtech:turbine_casing@4"
            ]
        },
        {
            "x": 4,
            "y": 4,
            "z": 4,
            "elements": [
                "gregtech:turbine_casing@4"
            ]
        },
        {
            "x": -3,
            "y": 1,
            "z": 4,
            "elements": [
                "gregtech:turbine_casing@4"
            ]
        },
        {
            "x": -3,
            "y": 1,
            "z": 0,
            "elements": [
                "gregtech:turbine_casing@4"
            ]
        },
        {
            "x": -5,
            "y": 2,
            "z": 1,
            "elements": [
                "gregtech:turbine_casing@4"
            ]
        },
        {
            "x": -1,
            "y": 0,
            "z": 3,
            "elements": [
                "gregtech:turbine_casing@4"
            ]
        },
        {
            "x": -1,
            "y": 0,
            "z": 2,
            "nbt": {"id":"ic2:fluid_pipe","ForgeCaps":{"nuclearcraft:capability_default_radiation_resistance":{"radiationResistance":"0.0d","shieldingRadResistance":"0.0d"}},"facing":"3b","active":"0b","components":{"covers":{"covers":[]}},"connectivity":"8b","covers":"0b","type":"1b","size":"3b","Empty":""},
            "elements": [
                "ic2:te@12"
            ]
        },
        {
            "x": -1,
            "y": 0,
            "z": 1,
            "elements": [
                "gregtech:turbine_casing@4"
            ]
        },
        {
            "x": 3,
            "y": 0,
            "z": 4,
            "elements": [
                "gregtech:turbine_casing@4"
            ]
        },
        {
            "x": 2,
            "y": 2,
            "z": 4,
            "elements": [
                "gregtech:turbine_casing@4"
            ]
        },
        {
            "x": -3,
            "y": 4,
            "z": 4,
            "elements": [
                "gregtech:turbine_casing@4"
            ]
        },
        {
            "x": -3,
            "y": 4,
            "z": 0,
            "elements": [
                "gregtech:turbine_casing@4"
            ]
        },
        {
            "x": 3,
            "y": 0,
            "z": 0,
            "elements": [
                "gregtech:turbine_casing@4"
            ]
        },
        {
            "x": 2,
            "y": 4,
            "z": 0,
            "elements": [
                "gregtech:turbine_casing@4"
            ]
        },
        {
            "x": 2,
            "y": -1,
            "z": 3,
            "elements": [
                "gregtech:metal_casing@4", "modularmachinery:blockinputfluid", "modularmachinery:blockoutputfluid"item", "modularmachinery:blockinputfluid", "modularmachinery:blockoutputfluid"energy", "modularmachinery:blockinputfluid", "modularmachinery:blockoutputfluid"
            ]
        },
        {
            "x": 2,
            "y": -1,
            "z": 2,
            "elements": [
                "gregtech:metal_casing@4", "modularmachinery:blockinputfluid", "modularmachinery:blockoutputfluid"item", "modularmachinery:blockinputfluid", "modularmachinery:blockoutputfluid"energy", "modularmachinery:blockinputfluid", "modularmachinery:blockoutputfluid"
            ]
        },
        {
            "x": 2,
            "y": -1,
            "z": 4,
            "elements": [
                "gregtech:metal_casing@4", "modularmachinery:blockinputfluid", "modularmachinery:blockoutputfluid"item", "modularmachinery:blockinputfluid", "modularmachinery:blockoutputfluid"energy", "modularmachinery:blockinputfluid", "modularmachinery:blockoutputfluid"
            ]
        },
        {
            "x": 2,
            "y": 4,
            "z": 4,
            "elements": [
                "gregtech:turbine_casing@4"
            ]
        },
        {
            "x": 2,
            "y": -1,
            "z": 1,
            "elements": [
                "gregtech:metal_casing@4", "modularmachinery:blockinputfluid", "modularmachinery:blockoutputfluid"item", "modularmachinery:blockinputfluid", "modularmachinery:blockoutputfluid"energy", "modularmachinery:blockinputfluid", "modularmachinery:blockoutputfluid"
            ]
        },
        {
            "x": 2,
            "y": -1,
            "z": 0,
            "elements": [
                "gregtech:metal_casing@4", "modularmachinery:blockinputfluid", "modularmachinery:blockoutputfluid"item", "modularmachinery:blockinputfluid", "modularmachinery:blockoutputfluid"energy", "modularmachinery:blockinputfluid", "modularmachinery:blockoutputfluid"
            ]
        },
        {
            "x": 5,
            "y": 1,
            "z": 2,
            "elements": [
                "gregtech:turbine_casing@4"
            ]
        },
        {
            "x": 5,
            "y": 1,
            "z": 1,
            "elements": [
                "gregtech:turbine_casing@4"
            ]
        },
        {
            "x": 5,
            "y": 1,
            "z": 3,
            "elements": [
                "gregtech:turbine_casing@4"
            ]
        },
        {
            "x": 3,
            "y": 3,
            "z": 0,
            "elements": [
                "gregtech:turbine_casing@4"
            ]
        },
        {
            "x": -4,
            "y": 0,
            "z": 0,
            "elements": [
                "gregtech:turbine_casing@4"
            ]
        },
        {
            "x": -3,
            "y": 2,
            "z": 0,
            "elements": [
                "gregtech:turbine_casing@4"
            ]
        },
        {
            "x": -1,
            "y": 2,
            "z": 1,
            "elements": [
                "gregtech:turbine_casing@4"
            ]
        },
        {
            "x": -3,
            "y": 2,
            "z": 4,
            "elements": [
                "gregtech:turbine_casing@4"
            ]
        },
        {
            "x": -1,
            "y": 2,
            "z": 3,
            "elements": [
                "gregtech:turbine_casing@4"
            ]
        },
        {
            "x": -1,
            "y": 2,
            "z": 2,
            "elements": [
                "gregtech:turbine_casing@4"
            ]
        },
        {
            "x": -4,
            "y": 0,
            "z": 4,
            "elements": [
                "gregtech:turbine_casing@4"
            ]
        },
        {
            "x": 4,
            "y": -1,
            "z": 4,
            "elements": [
                "gregtech:metal_casing@4", "modularmachinery:blockinputfluid", "modularmachinery:blockoutputfluid"item", "modularmachinery:blockinputfluid", "modularmachinery:blockoutputfluid"energy", "modularmachinery:blockinputfluid", "modularmachinery:blockoutputfluid"
            ]
        },
        {
            "x": -3,
            "y": -1,
            "z": 0,
            "elements": [
                "gregtech:metal_casing@4", "modularmachinery:blockinputfluid", "modularmachinery:blockoutputfluid"item", "modularmachinery:blockinputfluid", "modularmachinery:blockoutputfluid"energy", "modularmachinery:blockinputfluid", "modularmachinery:blockoutputfluid"
            ]
        },
        {
            "x": -3,
            "y": -1,
            "z": 1,
            "elements": [
                "gregtech:metal_casing@4", "modularmachinery:blockinputfluid", "modularmachinery:blockoutputfluid"item", "modularmachinery:blockinputfluid", "modularmachinery:blockoutputfluid"energy", "modularmachinery:blockinputfluid", "modularmachinery:blockoutputfluid"
            ]
        },
        {
            "x": -3,
            "y": -1,
            "z": 2,
            "elements": [
                "gregtech:metal_casing@4", "modularmachinery:blockinputfluid", "modularmachinery:blockoutputfluid"item", "modularmachinery:blockinputfluid", "modularmachinery:blockoutputfluid"energy", "modularmachinery:blockinputfluid", "modularmachinery:blockoutputfluid"
            ]
        },
        {
            "x": -4,
            "y": 3,
            "z": 0,
            "elements": [
                "gregtech:turbine_casing@4"
            ]
        },
        {
            "x": 4,
            "y": -1,
            "z": 0,
            "elements": [
                "gregtech:metal_casing@4", "modularmachinery:blockinputfluid", "modularmachinery:blockoutputfluid"item", "modularmachinery:blockinputfluid", "modularmachinery:blockoutputfluid"energy", "modularmachinery:blockinputfluid", "modularmachinery:blockoutputfluid"
            ]
        },
        {
            "x": -3,
            "y": -1,
            "z": 3,
            "elements": [
                "gregtech:metal_casing@4", "modularmachinery:blockinputfluid", "modularmachinery:blockoutputfluid"item", "modularmachinery:blockinputfluid", "modularmachinery:blockoutputfluid"energy", "modularmachinery:blockinputfluid", "modularmachinery:blockoutputfluid"
            ]
        },
        {
            "x": 4,
            "y": -1,
            "z": 1,
            "elements": [
                "gregtech:metal_casing@4", "modularmachinery:blockinputfluid", "modularmachinery:blockoutputfluid"item", "modularmachinery:blockinputfluid", "modularmachinery:blockoutputfluid"energy", "modularmachinery:blockinputfluid", "modularmachinery:blockoutputfluid"
            ]
        },
        {
            "x": -3,
            "y": -1,
            "z": 4,
            "elements": [
                "gregtech:metal_casing@4", "modularmachinery:blockinputfluid", "modularmachinery:blockoutputfluid"item", "modularmachinery:blockinputfluid", "modularmachinery:blockoutputfluid"energy", "modularmachinery:blockinputfluid", "modularmachinery:blockoutputfluid"
            ]
        },
        {
            "x": 3,
            "y": 3,
            "z": 4,
            "elements": [
                "gregtech:turbine_casing@4"
            ]
        },
        {
            "x": 4,
            "y": -1,
            "z": 2,
            "elements": [
                "gregtech:metal_casing@4", "modularmachinery:blockinputfluid", "modularmachinery:blockoutputfluid"item", "modularmachinery:blockinputfluid", "modularmachinery:blockoutputfluid"energy", "modularmachinery:blockinputfluid", "modularmachinery:blockoutputfluid"
            ]
        },
        {
            "x": -4,
            "y": 3,
            "z": 4,
            "elements": [
                "gregtech:turbine_casing@4"
            ]
        },
        {
            "x": 4,
            "y": -1,
            "z": 3,
            "elements": [
                "gregtech:metal_casing@4", "modularmachinery:blockinputfluid", "modularmachinery:blockoutputfluid"item", "modularmachinery:blockinputfluid", "modularmachinery:blockoutputfluid"energy", "modularmachinery:blockinputfluid", "modularmachinery:blockoutputfluid"
            ]
        }
    ]}